<?xml version="1.0" ?>
<!-- =================================================================================== -->
<!-- |    This document was hand generated for lite 6 and not autogenera.              | -->
<!-- |    EDITING THIS FILE BY HAND IS NOT RECOMMENDED                                 | -->
<!-- =================================================================================== -->
<robot name="lite6_urdf" xmlns:xacro="http://ros.org/wiki/xacro">
  <link name="link_base">
    <collision name="collision">
      <geometry>
        <mesh filename="package://abb_irb6600_support/meshes/irb6640/collision/base_link.stl"/>
      </geometry>
      <material name="yellow">
        <color rgba="0 1 1 1"/>
      </material>
    </collision>
    <visual name="visual">
      <geometry>
        <mesh filename="package://xarm_description/meshes/lite6/visual/base.stl"/>
      </geometry>
      <material name="white">
        <color rgba="255 255 255 1"/>
      </material>
    </visual>
  </link>
  <link name="link1">
    <collision name="collision">
      <geometry>
        <mesh filename="package://xarm_description/meshes/lite6/collision/link1.stl"/>
      </geometry>
      <material name="white"/>
    </collision>
    <visual name="visual">
      <geometry>
        <mesh filename="package://xarm_description/meshes/lite6/visual/link1.stl"/>
      </geometry>
      <material name="white"/>
    </visual>
  </link>
  <link name="link2">
    <collision name="collision">
      <geometry>
        <mesh filename="package://xarm_description/meshes/lite6/collision/link2.stl"/>
      </geometry>
      <material name="white"/>
    </collision>
    <visual name="visual">
      <geometry>
        <mesh filename="package://xarm_description/meshes/lite6/visual/link2.stl"/>
      </geometry>
      <material name="white"/>
    </visual>
  </link>
  <link name="link3">
    <collision name="collision">
      <geometry>
        <mesh filename="package://xarm_description/meshes/lite6/collision/link3.stl"/>
      </geometry>
      <material name="white"/>
    </collision>
    <visual name="visual">
      <geometry>
        <mesh filename="package://xarm_description/meshes/lite6/visual/link3.stl"/>
      </geometry>
      <material name="white"/>
    </visual>
  </link>
  <link name="link4">
    <collision name="collision">
      <geometry>
        <mesh filename="package://xarm_description/meshes/lite6/collision/link4.stl"/>
      </geometry>
      <material name="white"/>
    </collision>
    <visual name="visual">
      <geometry>
        <mesh filename="package://xarm_description/meshes/lite6/visual/link4.stl"/>
      </geometry>
      <material name="white"/>
    </visual>
  </link>
  <link name="link5">
    <collision name="white">
      <geometry>
        <mesh filename="package://xarm_description/meshes/lite6/collision/link5.stl"/>
      </geometry>
      <material name="white"/>
    </collision>
    <visual name="visual">
      <geometry>
        <mesh filename="package://xarm_description/meshes/lite6/visual/link5.stl"/>
      </geometry>
      <material name="white"/>
    </visual>
  </link>
  <link name="link_6">
    <collision name="white">
      <geometry>
        <mesh filename="package://xarm_description/meshes/lite6/collision/link6.stl"/>
      </geometry>
      <material name="white"/>
    </collision>
    <visual name="visual">
      <geometry>
        <mesh filename="package://xarm_description/meshes/lite6/visual/link6.stl"/>
      </geometry>
      <material name="white"/>
    </visual>
  </link>
  <joint name="joint1" type="revolute">
    <origin rpy="0 0 0" xyz="0 0 0.2433"/>
    <axis xyz="0 0 1"/>
    <parent link="link_base"/>
    <child link="link_1"/>
    <limit effort="32" lower="-6.28319" upper="6.28319" velocity="3.14"/>
  </joint>
  <joint name="joint2" type="revolute">
    <origin rpy="1.5708 -1.5708 3.1416" xyz="0 0 0"/>
    <axis xyz="0 0 1"/>
    <parent link="link1"/>
    <child link="link2"/>
    <limit effort="32" lower="-2.61799" upper="2.61799" velocity="3.14"/>
  </joint>
  <joint name="joint3" type="revolute">
    <origin rpy="-3.1416 0 1.5708" xyz="0.2 0 0"/>
    <axis xyz="0 1 0"/>
    <parent link="link2"/>
    <child link="link3"/>
    <limit effort="18" lower="-0.061087" upper="5.235988" velocity="3.14"/>
  </joint>
  <joint name="joint4" type="revolute">
    <origin rpy="1.5708 0 0" xyz="0.087 -0.2276 0"/>
    <axis xyz="0 0 1"/>
    <parent link="link3"/>
    <child link="link4"/>
    <limit effort="2.5" lower="-6.28319" upper="6.28319" velocity="3.14"/>
  </joint>
  <joint name="joint5" type="revolute">
    <origin rpy="1.5708 0 0" xyz="0 0 0 "/>
    <axis xyz="0 0 1"/>
    <parent link="link4"/>
    <child link="link5"/>
    <limit effort="2.5" lower="-2.1642" upper="2.1642" velocity="3.14"/>
  </joint>
  <joint name="joint6" type="revolute">
    <origin rpy="-1.5708 0 0" xyz="0 0.0615 0 "/>
    <axis xyz="0 0 1"/>
    <parent link="link5"/>
    <child link="link6"/>
    <limit effort="2.5" lower="-6.28319" upper="6.28319" velocity="3.14"/>
  </joint>
  <link name="base"/>
  <joint name="base_link-base" type="fixed">
    <origin rpy="0 0 0" xyz="0 0 0"/>
    <parent link="base_link"/>
    <child link="base"/>
  </joint>
</robot>

